2024-11-17 14:43:50.443 | INFO     | __main__:main:23 - running the application...
2024-11-17 14:43:50.450 | INFO     | model.model_inference:load_model:47 - checking the existance of model config file at model\models/rf_db_v3
2024-11-17 14:43:50.451 | INFO     | model.model_inference:load_model:59 - model rf_db_v3 exists! -> loading model configuration file
2024-11-17 14:43:54.845 | INFO     | model.model_inference:predict:80 - making prediction!
2024-11-17 14:43:54.862 | INFO     | __main__:main:39 - prediction = [1926.11476166]2024-11-17 14:49:25.525 | INFO     | __main__:main:23 - running the application...
2024-11-17 14:49:25.527 | INFO     | model.model_inference:load_model:47 - checking the existance of model config file at model\models/rf_db_v3
2024-11-17 14:49:25.527 | ERROR    | __main__:<module>:43 - An error has been caught in function '<module>', process 'MainProcess' (19164), thread 'MainThread' (14988):
Traceback (most recent call last):

> File "C:\Users\steve\Desktop\Notebooks\Production-Demo\src\runner_inference.py", line 43, in <module>
    main()
    └ <function main at 0x0000024458E03D80>

  File "C:\Users\steve\Desktop\Notebooks\Production-Demo\src\runner_inference.py", line 25, in main
    ml_svc.load_model()
    │      └ <function ModelInferenceService.load_model at 0x0000024458EF71A0>
    └ <model.model_inference.ModelInferenceService object at 0x0000024458EAC380>

  File "C:\Users\steve\Desktop\Notebooks\Production-Demo\src\model\model_inference.py", line 57, in load_model
    raise FileNotFoundError('Model file does not exist!')

FileNotFoundError: Model file does not exist!
2024-11-17 14:50:09.159 | INFO     | __main__:main:22 - running the application...
2024-11-17 14:50:09.160 | INFO     | model.model_builder:train_model:37 - building the model config file at model\models/rf_db_v3
2024-11-17 14:50:09.161 | INFO     | model.pipeline.model:build_model:34 - starting up model building pipeline
2024-11-17 14:50:09.161 | INFO     | model.pipeline.preparation:prepare_data:26 - starting up preprocessing pipeline
2024-11-17 14:50:09.161 | INFO     | model.pipeline.collection:load_data_from_db:26 - extracting the table from the database
2024-11-17 14:50:09.255 | INFO     | model.pipeline.preparation:_encode_cat_cols:43 - encoding categorical columns: ['balcony', 'parking', 'furnished', 'garage', 'storage']
2024-11-17 14:50:09.291 | INFO     | model.pipeline.preparation:_parse_garden_col:61 - pasring garden column
2024-11-17 14:50:09.293 | INFO     | model.pipeline.model:_get_x_y:83 - defining X and Y variables. X vars: ['area', 'constraction_year', 'bedrooms', 'garden', 'balcony_yes', 'parking_yes', 'furnished_yes', 'garage_yes', 'storage_yes']; y var: rent
2024-11-17 14:50:09.295 | INFO     | model.pipeline.model:_split_train_test:101 - splitting data into train and test sets
2024-11-17 14:50:09.311 | INFO     | model.pipeline.model:_train_model:123 - training a model with hyperparameters
2024-11-17 14:50:45.416 | INFO     | model.pipeline.model:_evaluate_model:163 - evaluating model performance. SCORE=0.6561175557334675
2024-11-17 14:50:45.417 | INFO     | model.pipeline.model:_save_model:178 - saving a model to a directory: model\models/rf_db_v3
2024-11-17 14:51:44.604 | INFO     | __main__:main:23 - running the application...
2024-11-17 14:51:44.606 | INFO     | model.model_inference:load_model:47 - checking the existance of model config file at model\models/rf_db_v3
2024-11-17 14:51:44.606 | INFO     | model.model_inference:load_model:59 - model rf_db_v3 exists! -> loading model configuration file
2024-11-17 14:51:49.248 | INFO     | model.model_inference:predict:80 - making prediction!
2024-11-17 14:51:49.372 | INFO     | __main__:main:39 - prediction = [1956.63824074]
